2025-05-02 09:52:59 [INFO] カラム 'OtherInvestments' を追加しました。
2025-05-02 09:52:59 [INFO] カラム 'TaxesReceivable' を追加しました。
2025-05-02 09:53:08 [INFO] カラム 'StockBasedCompensation' を追加しました。
2025-05-02 09:53:08 [INFO] カラム 'ResearchAndDevelopment' を追加しました。
2025-05-02 09:53:19 [INFO] カラム 'TotalOtherFinanceCost' を追加しました。
2025-05-02 09:54:58 [INFO] カラム 'DividendReceivedCFO' を追加しました。
2025-05-02 09:55:08 [INFO] カラム 'RestrictedCash' を追加しました。
2025-05-02 09:55:23 [INFO] カラム 'SaleOfIntangibles' を追加しました。
2025-05-02 09:55:37 [INFO] カラム 'SaleOfInvestmentProperties' を追加しました。
2025-05-02 10:00:57 [INFO] カラム 'splits' を追加しました。
2025-05-02 10:03:22 [INFO] カラム 'NonCurrentDeferredRevenue' を追加しました。
2025-05-02 10:07:39 [INFO] カラム 'InvestmentProperties' を追加しました。
2025-05-02 10:07:39 [INFO] カラム 'PurchaseOfInvestmentProperties' を追加しました。
2025-05-02 10:12:39 [INFO] カラム 'InvestmentsInOtherVenturesUnderEquityMethod' を追加しました。
2025-05-02 10:16:07 [INFO] カラム 'NetIncomeDiscontinuousOperations' を追加しました。
2025-05-02 10:17:17 [INFO] カラム 'ImpairmentOfCapitalAssets' を追加しました。
2025-05-02 10:18:18 [ERROR] 2193 のKPIデータ取得中にエラー:
Traceback (most recent call last):
  File "C:\python311\lib\site-packages\urllib3\response.py", line 705, in _error_catcher
    yield
  File "C:\python311\lib\site-packages\urllib3\response.py", line 1072, in read_chunked
    self._update_chunk_length()
  File "C:\python311\lib\site-packages\urllib3\response.py", line 1000, in _update_chunk_length
    line = self._fp.fp.readline()  # type: ignore[union-attr]
           ^^^^^^^^^^^^^^^^^^^^^^
  File "C:\Python311\Lib\socket.py", line 706, in readinto
    return self._sock.recv_into(b)
           ^^^^^^^^^^^^^^^^^^^^^^^
  File "C:\Python311\Lib\ssl.py", line 1278, in recv_into
    return self.read(nbytes, buffer)
           ^^^^^^^^^^^^^^^^^^^^^^^^^
  File "C:\Python311\Lib\ssl.py", line 1134, in read
    return self._sslobj.read(len, buffer)
           ^^^^^^^^^^^^^^^^^^^^^^^^^^^^^^
TimeoutError: The read operation timed out

The above exception was the direct cause of the following exception:

Traceback (most recent call last):
  File "C:\python311\lib\site-packages\requests\models.py", line 816, in generate
    yield from self.raw.stream(chunk_size, decode_content=True)
  File "C:\python311\lib\site-packages\urllib3\response.py", line 932, in stream
    yield from self.read_chunked(amt, decode_content=decode_content)
  File "C:\python311\lib\site-packages\urllib3\response.py", line 1060, in read_chunked
    with self._error_catcher():
  File "C:\Python311\Lib\contextlib.py", line 155, in __exit__
    self.gen.throw(typ, value, traceback)
  File "C:\python311\lib\site-packages\urllib3\response.py", line 710, in _error_catcher
    raise ReadTimeoutError(self._pool, None, "Read timed out.") from e  # type: ignore[arg-type]
    ^^^^^^^^^^^^^^^^^^^^^^^^^^^^^^^^^^^^^^^^^^^^^^^^^^^^^^^^^^^^^^^^^^
urllib3.exceptions.ReadTimeoutError: HTTPSConnectionPool(host='finance.yahoo.com', port=443): Read timed out.

During handling of the above exception, another exception occurred:

Traceback (most recent call last):
  File "c:\Users\Owner\Desktop\FlaskPractice\get_yahooquery.py", line 60, in get_financial_data
    ticker = Ticker(symbol + '.T')
             ^^^^^^^^^^^^^^^^^^^^^
  File "C:\python311\lib\site-packages\yahooquery\ticker.py", line 93, in __init__
    super(Ticker, self).__init__(**kwargs)
  File "C:\python311\lib\site-packages\yahooquery\base.py", line 950, in __init__
    self.session = setup_session(self.session, self._setup_url)
                   ^^^^^^^^^^^^^^^^^^^^^^^^^^^^^^^^^^^^^^^^^^^^
  File "C:\python311\lib\site-packages\yahooquery\utils\__init__.py", line 1373, in setup_session
    response = session.get(url, allow_redirects=True)
               ^^^^^^^^^^^^^^^^^^^^^^^^^^^^^^^^^^^^^^
  File "C:\python311\lib\site-packages\requests\sessions.py", line 602, in get
    return self.request("GET", url, **kwargs)
           ^^^^^^^^^^^^^^^^^^^^^^^^^^^^^^^^^^
  File "C:\python311\lib\site-packages\requests\sessions.py", line 589, in request
    resp = self.send(prep, **send_kwargs)
           ^^^^^^^^^^^^^^^^^^^^^^^^^^^^^^
  File "C:\python311\lib\site-packages\requests\sessions.py", line 747, in send
    r.content
  File "C:\python311\lib\site-packages\requests\models.py", line 899, in content
    self._content = b"".join(self.iter_content(CONTENT_CHUNK_SIZE)) or b""
                    ^^^^^^^^^^^^^^^^^^^^^^^^^^^^^^^^^^^^^^^^^^^^^^^
  File "C:\python311\lib\site-packages\requests\models.py", line 822, in generate
    raise ConnectionError(e)
requests.exceptions.ConnectionError: HTTPSConnectionPool(host='finance.yahoo.com', port=443): Read timed out.

